2025-05-05 19:14:25,103 - discord_bot - INFO - Bot starting up...
2025-05-05 19:14:28,650 - werkzeug - INFO - 192.168.11.20 - - [05/May/2025 19:14:28] "GET / HTTP/1.1" 200 -
2025-05-05 19:14:28,720 - werkzeug - INFO - 192.168.11.20 - - [05/May/2025 19:14:28] "GET /api/bot-status?api_key=025002 HTTP/1.1" 200 -
2025-05-05 19:14:28,780 - werkzeug - INFO - 192.168.11.20 - - [05/May/2025 19:14:28] "[31m[1mGET /api/member-count?api_key=025002 HTTP/1.1[0m" 400 -
2025-05-05 19:14:29,197 - werkzeug - INFO - 192.168.11.20 - - [05/May/2025 19:14:29] "[31m[1mGET /api/members?api_key=025002 HTTP/1.1[0m" 400 -
2025-05-05 19:14:30,109 - discord_bot - INFO - Mock context initialized with guild: Zorzi's server
2025-05-05 19:14:30,109 - discord_bot - INFO - Bot started successfully
2025-05-05 19:14:30,110 - werkzeug - INFO - 192.168.11.20 - - [05/May/2025 19:14:30] "POST /api/start-bot?api_key=025002 HTTP/1.1" 200 -
2025-05-05 19:14:30,219 - werkzeug - INFO - 192.168.11.20 - - [05/May/2025 19:14:30] "GET /api/members?api_key=025002 HTTP/1.1" 200 -
2025-05-05 19:14:33,626 - werkzeug - INFO - 192.168.11.20 - - [05/May/2025 19:14:33] "GET / HTTP/1.1" 200 -
2025-05-05 19:14:33,698 - werkzeug - INFO - 192.168.11.20 - - [05/May/2025 19:14:33] "GET /api/bot-status?api_key=025002 HTTP/1.1" 200 -
2025-05-05 19:14:33,759 - werkzeug - INFO - 192.168.11.20 - - [05/May/2025 19:14:33] "GET /api/member-count?api_key=025002 HTTP/1.1" 200 -
2025-05-05 19:14:36,262 - werkzeug - INFO - 192.168.11.20 - - [05/May/2025 19:14:36] "[31m[1mPOST /api/hello?api_key=025002&member=1368932877961662658&message=Levski HTTP/1.1[0m" 400 -
2025-05-05 19:14:37,101 - werkzeug - INFO - 192.168.11.20 - - [05/May/2025 19:14:37] "[31m[1mPOST /api/hello?api_key=025002&member=1368932877961662658&message=Levski HTTP/1.1[0m" 400 -
2025-05-05 19:14:38,630 - werkzeug - INFO - 192.168.11.20 - - [05/May/2025 19:14:38] "GET / HTTP/1.1" 200 -
2025-05-05 19:14:38,701 - werkzeug - INFO - 192.168.11.20 - - [05/May/2025 19:14:38] "GET /api/bot-status?api_key=025002 HTTP/1.1" 200 -
2025-05-05 19:14:38,767 - werkzeug - INFO - 192.168.11.20 - - [05/May/2025 19:14:38] "GET /api/member-count?api_key=025002 HTTP/1.1" 200 -
2025-05-05 19:14:43,702 - werkzeug - INFO - 192.168.11.20 - - [05/May/2025 19:14:43] "GET / HTTP/1.1" 200 -
2025-05-05 19:14:43,861 - werkzeug - INFO - 192.168.11.20 - - [05/May/2025 19:14:43] "GET /api/bot-status?api_key=025002 HTTP/1.1" 200 -
2025-05-05 19:14:43,922 - werkzeug - INFO - 192.168.11.20 - - [05/May/2025 19:14:43] "GET /api/member-count?api_key=025002 HTTP/1.1" 200 -
2025-05-05 19:14:48,624 - werkzeug - INFO - 192.168.11.20 - - [05/May/2025 19:14:48] "GET / HTTP/1.1" 200 -
2025-05-05 19:14:48,692 - werkzeug - INFO - 192.168.11.20 - - [05/May/2025 19:14:48] "GET /api/bot-status?api_key=025002 HTTP/1.1" 200 -
2025-05-05 19:14:48,753 - werkzeug - INFO - 192.168.11.20 - - [05/May/2025 19:14:48] "GET /api/member-count?api_key=025002 HTTP/1.1" 200 -
2025-05-05 19:14:51,700 - werkzeug - INFO - 192.168.11.20 - - [05/May/2025 19:14:51] "GET / HTTP/1.1" 200 -
2025-05-05 19:14:51,767 - werkzeug - INFO - 192.168.11.20 - - [05/May/2025 19:14:51] "GET /api/bot-status?api_key=025002 HTTP/1.1" 200 -
2025-05-05 19:14:51,825 - werkzeug - INFO - 192.168.11.20 - - [05/May/2025 19:14:51] "GET /api/member-count?api_key=025002 HTTP/1.1" 200 -
2025-05-05 19:14:52,861 - werkzeug - INFO - 192.168.11.20 - - [05/May/2025 19:14:52] "GET /api/members?api_key=025002 HTTP/1.1" 200 -
2025-05-05 19:14:52,927 - werkzeug - INFO - 192.168.11.20 - - [05/May/2025 19:14:52] "GET /api/roles?api_key=025002 HTTP/1.1" 200 -
2025-05-05 19:14:53,845 - werkzeug - INFO - 192.168.11.20 - - [05/May/2025 19:14:53] "GET / HTTP/1.1" 200 -
2025-05-05 19:14:53,912 - werkzeug - INFO - 192.168.11.20 - - [05/May/2025 19:14:53] "GET /api/bot-status?api_key=025002 HTTP/1.1" 200 -
2025-05-05 19:14:53,974 - werkzeug - INFO - 192.168.11.20 - - [05/May/2025 19:14:53] "GET /api/member-count?api_key=025002 HTTP/1.1" 200 -
2025-05-05 19:14:58,507 - werkzeug - INFO - 192.168.11.20 - - [05/May/2025 19:14:58] "POST /api/give-member-role?api_key=025002&role_id=1348675353626808340&user_id=1368932877961662658 HTTP/1.1" 200 -
2025-05-05 19:14:58,616 - werkzeug - INFO - 192.168.11.20 - - [05/May/2025 19:14:58] "GET / HTTP/1.1" 200 -
2025-05-05 19:14:58,682 - werkzeug - INFO - 192.168.11.20 - - [05/May/2025 19:14:58] "GET /api/bot-status?api_key=025002 HTTP/1.1" 200 -
2025-05-05 19:14:58,742 - werkzeug - INFO - 192.168.11.20 - - [05/May/2025 19:14:58] "GET /api/member-count?api_key=025002 HTTP/1.1" 200 -
2025-05-05 19:15:03,754 - werkzeug - INFO - 192.168.11.20 - - [05/May/2025 19:15:03] "GET / HTTP/1.1" 200 -
2025-05-05 19:15:03,830 - werkzeug - INFO - 192.168.11.20 - - [05/May/2025 19:15:03] "GET /api/bot-status?api_key=025002 HTTP/1.1" 200 -
2025-05-05 19:15:03,901 - werkzeug - INFO - 192.168.11.20 - - [05/May/2025 19:15:03] "GET /api/member-count?api_key=025002 HTTP/1.1" 200 -
2025-05-05 19:15:05,718 - werkzeug - INFO - 192.168.11.20 - - [05/May/2025 19:15:05] "GET / HTTP/1.1" 200 -
2025-05-05 19:15:05,785 - werkzeug - INFO - 192.168.11.20 - - [05/May/2025 19:15:05] "GET /api/bot-status?api_key=025002 HTTP/1.1" 200 -
2025-05-05 19:15:05,900 - werkzeug - INFO - 192.168.11.20 - - [05/May/2025 19:15:05] "GET /api/member-count?api_key=025002 HTTP/1.1" 200 -
2025-05-05 19:15:08,627 - werkzeug - INFO - 192.168.11.20 - - [05/May/2025 19:15:08] "GET / HTTP/1.1" 200 -
2025-05-05 19:15:08,713 - werkzeug - INFO - 192.168.11.20 - - [05/May/2025 19:15:08] "GET /api/bot-status?api_key=025002 HTTP/1.1" 200 -
2025-05-05 19:15:08,773 - werkzeug - INFO - 192.168.11.20 - - [05/May/2025 19:15:08] "GET /api/member-count?api_key=025002 HTTP/1.1" 200 -
2025-05-05 19:15:13,506 - werkzeug - INFO - 192.168.11.20 - - [05/May/2025 19:15:13] "GET /api/data/attendance?api_key=025002 HTTP/1.1" 200 -
2025-05-05 19:15:13,732 - werkzeug - INFO - 192.168.11.20 - - [05/May/2025 19:15:13] "GET / HTTP/1.1" 200 -
2025-05-05 19:15:13,838 - werkzeug - INFO - 192.168.11.20 - - [05/May/2025 19:15:13] "GET /api/bot-status?api_key=025002 HTTP/1.1" 200 -
2025-05-05 19:15:13,900 - werkzeug - INFO - 192.168.11.20 - - [05/May/2025 19:15:13] "GET /api/member-count?api_key=025002 HTTP/1.1" 200 -
2025-05-05 19:15:17,211 - werkzeug - INFO - 192.168.11.20 - - [05/May/2025 19:15:17] "POST /api/attendance?api_key=025002&status=start&target_user_id=234339929159761920&group_id=g2 HTTP/1.1" 200 -
2025-05-05 19:15:18,624 - werkzeug - INFO - 192.168.11.20 - - [05/May/2025 19:15:18] "GET / HTTP/1.1" 200 -
2025-05-05 19:15:18,694 - werkzeug - INFO - 192.168.11.20 - - [05/May/2025 19:15:18] "GET /api/bot-status?api_key=025002 HTTP/1.1" 200 -
2025-05-05 19:15:18,758 - werkzeug - INFO - 192.168.11.20 - - [05/May/2025 19:15:18] "GET /api/member-count?api_key=025002 HTTP/1.1" 200 -
2025-05-05 19:15:23,684 - werkzeug - INFO - 192.168.11.20 - - [05/May/2025 19:15:23] "GET / HTTP/1.1" 200 -
2025-05-05 19:15:23,748 - werkzeug - INFO - 192.168.11.20 - - [05/May/2025 19:15:23] "GET /api/bot-status?api_key=025002 HTTP/1.1" 200 -
2025-05-05 19:15:23,809 - werkzeug - INFO - 192.168.11.20 - - [05/May/2025 19:15:23] "GET /api/member-count?api_key=025002 HTTP/1.1" 200 -
2025-05-05 19:15:28,627 - werkzeug - INFO - 192.168.11.20 - - [05/May/2025 19:15:28] "GET / HTTP/1.1" 200 -
2025-05-05 19:15:28,697 - werkzeug - INFO - 192.168.11.20 - - [05/May/2025 19:15:28] "GET /api/bot-status?api_key=025002 HTTP/1.1" 200 -
2025-05-05 19:15:28,746 - werkzeug - INFO - 192.168.11.20 - - [05/May/2025 19:15:28] "GET /api/member-count?api_key=025002 HTTP/1.1" 200 -
2025-05-05 19:15:33,647 - werkzeug - INFO - 192.168.11.20 - - [05/May/2025 19:15:33] "GET / HTTP/1.1" 200 -
2025-05-05 19:15:33,717 - werkzeug - INFO - 192.168.11.20 - - [05/May/2025 19:15:33] "GET /api/bot-status?api_key=025002 HTTP/1.1" 200 -
2025-05-05 19:15:33,778 - werkzeug - INFO - 192.168.11.20 - - [05/May/2025 19:15:33] "GET /api/member-count?api_key=025002 HTTP/1.1" 200 -
2025-05-05 19:15:38,632 - werkzeug - INFO - 192.168.11.20 - - [05/May/2025 19:15:38] "GET / HTTP/1.1" 200 -
2025-05-05 19:15:38,703 - werkzeug - INFO - 192.168.11.20 - - [05/May/2025 19:15:38] "GET /api/bot-status?api_key=025002 HTTP/1.1" 200 -
2025-05-05 19:15:38,761 - werkzeug - INFO - 192.168.11.20 - - [05/May/2025 19:15:38] "GET /api/member-count?api_key=025002 HTTP/1.1" 200 -
2025-05-05 19:21:42,913 - discord.gateway - WARNING - Can't keep up, shard ID None websocket is 15.4s behind.
2025-05-05 19:27:44,646 - discord.gateway - WARNING - Can't keep up, shard ID None websocket is 24.2s behind.
2025-05-05 20:38:12,017 - discord.client - ERROR - Attempting a reconnect in 0.15s
Traceback (most recent call last):
  File "/Users/campusheilbronn/PycharmProjects/TUMDiscordBot/.venv/lib/python3.12/site-packages/aiohttp/connector.py", line 1345, in _create_direct_connection
    hosts = await self._resolve_host(host, port, traces=traces)
            ^^^^^^^^^^^^^^^^^^^^^^^^^^^^^^^^^^^^^^^^^^^^^^^^^^^
  File "/Users/campusheilbronn/PycharmProjects/TUMDiscordBot/.venv/lib/python3.12/site-packages/aiohttp/connector.py", line 989, in _resolve_host
    return await asyncio.shield(resolved_host_task)
           ^^^^^^^^^^^^^^^^^^^^^^^^^^^^^^^^^^^^^^^^
  File "/Users/campusheilbronn/PycharmProjects/TUMDiscordBot/.venv/lib/python3.12/site-packages/aiohttp/connector.py", line 1020, in _resolve_host_with_throttle
    addrs = await self._resolver.resolve(host, port, family=self._family)
            ^^^^^^^^^^^^^^^^^^^^^^^^^^^^^^^^^^^^^^^^^^^^^^^^^^^^^^^^^^^^^
  File "/Users/campusheilbronn/PycharmProjects/TUMDiscordBot/.venv/lib/python3.12/site-packages/aiohttp/resolver.py", line 36, in resolve
    infos = await self._loop.getaddrinfo(
            ^^^^^^^^^^^^^^^^^^^^^^^^^^^^^
  File "/Library/Frameworks/Python.framework/Versions/3.12/lib/python3.12/asyncio/base_events.py", line 901, in getaddrinfo
    return await self.run_in_executor(
           ^^^^^^^^^^^^^^^^^^^^^^^^^^^
  File "/Library/Frameworks/Python.framework/Versions/3.12/lib/python3.12/concurrent/futures/thread.py", line 58, in run
    result = self.fn(*self.args, **self.kwargs)
             ^^^^^^^^^^^^^^^^^^^^^^^^^^^^^^^^^^
  File "/Library/Frameworks/Python.framework/Versions/3.12/lib/python3.12/socket.py", line 976, in getaddrinfo
    for res in _socket.getaddrinfo(host, port, family, type, proto, flags):
               ^^^^^^^^^^^^^^^^^^^^^^^^^^^^^^^^^^^^^^^^^^^^^^^^^^^^^^^^^^^
socket.gaierror: [Errno 8] nodename nor servname provided, or not known

The above exception was the direct cause of the following exception:

Traceback (most recent call last):
  File "/Users/campusheilbronn/PycharmProjects/TUMDiscordBot/.venv/lib/python3.12/site-packages/discord/client.py", line 598, in connect
    self.ws = await asyncio.wait_for(coro, timeout=60.0)
              ^^^^^^^^^^^^^^^^^^^^^^^^^^^^^^^^^^^^^^^^^^
  File "/Library/Frameworks/Python.framework/Versions/3.12/lib/python3.12/asyncio/tasks.py", line 520, in wait_for
    return await fut
           ^^^^^^^^^
  File "/Users/campusheilbronn/PycharmProjects/TUMDiscordBot/.venv/lib/python3.12/site-packages/discord/gateway.py", line 338, in from_client
    gateway = gateway or await client.http.get_gateway()
                         ^^^^^^^^^^^^^^^^^^^^^^^^^^^^^^^
  File "/Users/campusheilbronn/PycharmProjects/TUMDiscordBot/.venv/lib/python3.12/site-packages/discord/http.py", line 2999, in get_gateway
    data = await self.request(Route("GET", "/gateway"))
           ^^^^^^^^^^^^^^^^^^^^^^^^^^^^^^^^^^^^^^^^^^^^
  File "/Users/campusheilbronn/PycharmProjects/TUMDiscordBot/.venv/lib/python3.12/site-packages/discord/http.py", line 285, in request
    async with self.__session.request(
               ^^^^^^^^^^^^^^^^^^^^^^^
  File "/Users/campusheilbronn/PycharmProjects/TUMDiscordBot/.venv/lib/python3.12/site-packages/aiohttp/client.py", line 1423, in __aenter__
    self._resp: _RetType = await self._coro
                           ^^^^^^^^^^^^^^^^
  File "/Users/campusheilbronn/PycharmProjects/TUMDiscordBot/.venv/lib/python3.12/site-packages/aiohttp/client.py", line 701, in _request
    conn = await self._connector.connect(
           ^^^^^^^^^^^^^^^^^^^^^^^^^^^^^^
  File "/Users/campusheilbronn/PycharmProjects/TUMDiscordBot/.venv/lib/python3.12/site-packages/aiohttp/connector.py", line 544, in connect
    proto = await self._create_connection(req, traces, timeout)
            ^^^^^^^^^^^^^^^^^^^^^^^^^^^^^^^^^^^^^^^^^^^^^^^^^^^
  File "/Users/campusheilbronn/PycharmProjects/TUMDiscordBot/.venv/lib/python3.12/site-packages/aiohttp/connector.py", line 1050, in _create_connection
    _, proto = await self._create_direct_connection(req, traces, timeout)
               ^^^^^^^^^^^^^^^^^^^^^^^^^^^^^^^^^^^^^^^^^^^^^^^^^^^^^^^^^^
  File "/Users/campusheilbronn/PycharmProjects/TUMDiscordBot/.venv/lib/python3.12/site-packages/aiohttp/connector.py", line 1351, in _create_direct_connection
    raise ClientConnectorDNSError(req.connection_key, exc) from exc
aiohttp.client_exceptions.ClientConnectorDNSError: Cannot connect to host discord.com:443 ssl:default [nodename nor servname provided, or not known]
2025-05-05 20:38:12,191 - discord.client - ERROR - Attempting a reconnect in 1.52s
Traceback (most recent call last):
  File "/Users/campusheilbronn/PycharmProjects/TUMDiscordBot/.venv/lib/python3.12/site-packages/aiohttp/connector.py", line 1345, in _create_direct_connection
    hosts = await self._resolve_host(host, port, traces=traces)
            ^^^^^^^^^^^^^^^^^^^^^^^^^^^^^^^^^^^^^^^^^^^^^^^^^^^
  File "/Users/campusheilbronn/PycharmProjects/TUMDiscordBot/.venv/lib/python3.12/site-packages/aiohttp/connector.py", line 989, in _resolve_host
    return await asyncio.shield(resolved_host_task)
           ^^^^^^^^^^^^^^^^^^^^^^^^^^^^^^^^^^^^^^^^
  File "/Users/campusheilbronn/PycharmProjects/TUMDiscordBot/.venv/lib/python3.12/site-packages/aiohttp/connector.py", line 1020, in _resolve_host_with_throttle
    addrs = await self._resolver.resolve(host, port, family=self._family)
            ^^^^^^^^^^^^^^^^^^^^^^^^^^^^^^^^^^^^^^^^^^^^^^^^^^^^^^^^^^^^^
  File "/Users/campusheilbronn/PycharmProjects/TUMDiscordBot/.venv/lib/python3.12/site-packages/aiohttp/resolver.py", line 36, in resolve
    infos = await self._loop.getaddrinfo(
            ^^^^^^^^^^^^^^^^^^^^^^^^^^^^^
  File "/Library/Frameworks/Python.framework/Versions/3.12/lib/python3.12/asyncio/base_events.py", line 901, in getaddrinfo
    return await self.run_in_executor(
           ^^^^^^^^^^^^^^^^^^^^^^^^^^^
  File "/Library/Frameworks/Python.framework/Versions/3.12/lib/python3.12/concurrent/futures/thread.py", line 58, in run
    result = self.fn(*self.args, **self.kwargs)
             ^^^^^^^^^^^^^^^^^^^^^^^^^^^^^^^^^^
  File "/Library/Frameworks/Python.framework/Versions/3.12/lib/python3.12/socket.py", line 976, in getaddrinfo
    for res in _socket.getaddrinfo(host, port, family, type, proto, flags):
               ^^^^^^^^^^^^^^^^^^^^^^^^^^^^^^^^^^^^^^^^^^^^^^^^^^^^^^^^^^^
socket.gaierror: [Errno 8] nodename nor servname provided, or not known

The above exception was the direct cause of the following exception:

Traceback (most recent call last):
  File "/Users/campusheilbronn/PycharmProjects/TUMDiscordBot/.venv/lib/python3.12/site-packages/discord/client.py", line 598, in connect
    self.ws = await asyncio.wait_for(coro, timeout=60.0)
              ^^^^^^^^^^^^^^^^^^^^^^^^^^^^^^^^^^^^^^^^^^
  File "/Library/Frameworks/Python.framework/Versions/3.12/lib/python3.12/asyncio/tasks.py", line 520, in wait_for
    return await fut
           ^^^^^^^^^
  File "/Users/campusheilbronn/PycharmProjects/TUMDiscordBot/.venv/lib/python3.12/site-packages/discord/gateway.py", line 338, in from_client
    gateway = gateway or await client.http.get_gateway()
                         ^^^^^^^^^^^^^^^^^^^^^^^^^^^^^^^
  File "/Users/campusheilbronn/PycharmProjects/TUMDiscordBot/.venv/lib/python3.12/site-packages/discord/http.py", line 2999, in get_gateway
    data = await self.request(Route("GET", "/gateway"))
           ^^^^^^^^^^^^^^^^^^^^^^^^^^^^^^^^^^^^^^^^^^^^
  File "/Users/campusheilbronn/PycharmProjects/TUMDiscordBot/.venv/lib/python3.12/site-packages/discord/http.py", line 285, in request
    async with self.__session.request(
               ^^^^^^^^^^^^^^^^^^^^^^^
  File "/Users/campusheilbronn/PycharmProjects/TUMDiscordBot/.venv/lib/python3.12/site-packages/aiohttp/client.py", line 1423, in __aenter__
    self._resp: _RetType = await self._coro
                           ^^^^^^^^^^^^^^^^
  File "/Users/campusheilbronn/PycharmProjects/TUMDiscordBot/.venv/lib/python3.12/site-packages/aiohttp/client.py", line 701, in _request
    conn = await self._connector.connect(
           ^^^^^^^^^^^^^^^^^^^^^^^^^^^^^^
  File "/Users/campusheilbronn/PycharmProjects/TUMDiscordBot/.venv/lib/python3.12/site-packages/aiohttp/connector.py", line 544, in connect
    proto = await self._create_connection(req, traces, timeout)
            ^^^^^^^^^^^^^^^^^^^^^^^^^^^^^^^^^^^^^^^^^^^^^^^^^^^
  File "/Users/campusheilbronn/PycharmProjects/TUMDiscordBot/.venv/lib/python3.12/site-packages/aiohttp/connector.py", line 1050, in _create_connection
    _, proto = await self._create_direct_connection(req, traces, timeout)
               ^^^^^^^^^^^^^^^^^^^^^^^^^^^^^^^^^^^^^^^^^^^^^^^^^^^^^^^^^^
  File "/Users/campusheilbronn/PycharmProjects/TUMDiscordBot/.venv/lib/python3.12/site-packages/aiohttp/connector.py", line 1351, in _create_direct_connection
    raise ClientConnectorDNSError(req.connection_key, exc) from exc
aiohttp.client_exceptions.ClientConnectorDNSError: Cannot connect to host discord.com:443 ssl:default [nodename nor servname provided, or not known]
2025-05-05 20:38:13,723 - discord.client - ERROR - Attempting a reconnect in 5.83s
Traceback (most recent call last):
  File "/Users/campusheilbronn/PycharmProjects/TUMDiscordBot/.venv/lib/python3.12/site-packages/aiohttp/connector.py", line 1345, in _create_direct_connection
    hosts = await self._resolve_host(host, port, traces=traces)
            ^^^^^^^^^^^^^^^^^^^^^^^^^^^^^^^^^^^^^^^^^^^^^^^^^^^
  File "/Users/campusheilbronn/PycharmProjects/TUMDiscordBot/.venv/lib/python3.12/site-packages/aiohttp/connector.py", line 989, in _resolve_host
    return await asyncio.shield(resolved_host_task)
           ^^^^^^^^^^^^^^^^^^^^^^^^^^^^^^^^^^^^^^^^
  File "/Users/campusheilbronn/PycharmProjects/TUMDiscordBot/.venv/lib/python3.12/site-packages/aiohttp/connector.py", line 1020, in _resolve_host_with_throttle
    addrs = await self._resolver.resolve(host, port, family=self._family)
            ^^^^^^^^^^^^^^^^^^^^^^^^^^^^^^^^^^^^^^^^^^^^^^^^^^^^^^^^^^^^^
  File "/Users/campusheilbronn/PycharmProjects/TUMDiscordBot/.venv/lib/python3.12/site-packages/aiohttp/resolver.py", line 36, in resolve
    infos = await self._loop.getaddrinfo(
            ^^^^^^^^^^^^^^^^^^^^^^^^^^^^^
  File "/Library/Frameworks/Python.framework/Versions/3.12/lib/python3.12/asyncio/base_events.py", line 901, in getaddrinfo
    return await self.run_in_executor(
           ^^^^^^^^^^^^^^^^^^^^^^^^^^^
  File "/Library/Frameworks/Python.framework/Versions/3.12/lib/python3.12/concurrent/futures/thread.py", line 58, in run
    result = self.fn(*self.args, **self.kwargs)
             ^^^^^^^^^^^^^^^^^^^^^^^^^^^^^^^^^^
  File "/Library/Frameworks/Python.framework/Versions/3.12/lib/python3.12/socket.py", line 976, in getaddrinfo
    for res in _socket.getaddrinfo(host, port, family, type, proto, flags):
               ^^^^^^^^^^^^^^^^^^^^^^^^^^^^^^^^^^^^^^^^^^^^^^^^^^^^^^^^^^^
socket.gaierror: [Errno 8] nodename nor servname provided, or not known

The above exception was the direct cause of the following exception:

Traceback (most recent call last):
  File "/Users/campusheilbronn/PycharmProjects/TUMDiscordBot/.venv/lib/python3.12/site-packages/discord/client.py", line 598, in connect
    self.ws = await asyncio.wait_for(coro, timeout=60.0)
              ^^^^^^^^^^^^^^^^^^^^^^^^^^^^^^^^^^^^^^^^^^
  File "/Library/Frameworks/Python.framework/Versions/3.12/lib/python3.12/asyncio/tasks.py", line 520, in wait_for
    return await fut
           ^^^^^^^^^
  File "/Users/campusheilbronn/PycharmProjects/TUMDiscordBot/.venv/lib/python3.12/site-packages/discord/gateway.py", line 338, in from_client
    gateway = gateway or await client.http.get_gateway()
                         ^^^^^^^^^^^^^^^^^^^^^^^^^^^^^^^
  File "/Users/campusheilbronn/PycharmProjects/TUMDiscordBot/.venv/lib/python3.12/site-packages/discord/http.py", line 2999, in get_gateway
    data = await self.request(Route("GET", "/gateway"))
           ^^^^^^^^^^^^^^^^^^^^^^^^^^^^^^^^^^^^^^^^^^^^
  File "/Users/campusheilbronn/PycharmProjects/TUMDiscordBot/.venv/lib/python3.12/site-packages/discord/http.py", line 285, in request
    async with self.__session.request(
               ^^^^^^^^^^^^^^^^^^^^^^^
  File "/Users/campusheilbronn/PycharmProjects/TUMDiscordBot/.venv/lib/python3.12/site-packages/aiohttp/client.py", line 1423, in __aenter__
    self._resp: _RetType = await self._coro
                           ^^^^^^^^^^^^^^^^
  File "/Users/campusheilbronn/PycharmProjects/TUMDiscordBot/.venv/lib/python3.12/site-packages/aiohttp/client.py", line 701, in _request
    conn = await self._connector.connect(
           ^^^^^^^^^^^^^^^^^^^^^^^^^^^^^^
  File "/Users/campusheilbronn/PycharmProjects/TUMDiscordBot/.venv/lib/python3.12/site-packages/aiohttp/connector.py", line 544, in connect
    proto = await self._create_connection(req, traces, timeout)
            ^^^^^^^^^^^^^^^^^^^^^^^^^^^^^^^^^^^^^^^^^^^^^^^^^^^
  File "/Users/campusheilbronn/PycharmProjects/TUMDiscordBot/.venv/lib/python3.12/site-packages/aiohttp/connector.py", line 1050, in _create_connection
    _, proto = await self._create_direct_connection(req, traces, timeout)
               ^^^^^^^^^^^^^^^^^^^^^^^^^^^^^^^^^^^^^^^^^^^^^^^^^^^^^^^^^^
  File "/Users/campusheilbronn/PycharmProjects/TUMDiscordBot/.venv/lib/python3.12/site-packages/aiohttp/connector.py", line 1351, in _create_direct_connection
    raise ClientConnectorDNSError(req.connection_key, exc) from exc
aiohttp.client_exceptions.ClientConnectorDNSError: Cannot connect to host discord.com:443 ssl:default [nodename nor servname provided, or not known]
2025-05-05 20:48:03,489 - discord.client - ERROR - Attempting a reconnect in 14.44s
Traceback (most recent call last):
  File "/Users/campusheilbronn/PycharmProjects/TUMDiscordBot/.venv/lib/python3.12/site-packages/aiohttp/connector.py", line 1345, in _create_direct_connection
    hosts = await self._resolve_host(host, port, traces=traces)
            ^^^^^^^^^^^^^^^^^^^^^^^^^^^^^^^^^^^^^^^^^^^^^^^^^^^
  File "/Users/campusheilbronn/PycharmProjects/TUMDiscordBot/.venv/lib/python3.12/site-packages/aiohttp/connector.py", line 989, in _resolve_host
    return await asyncio.shield(resolved_host_task)
           ^^^^^^^^^^^^^^^^^^^^^^^^^^^^^^^^^^^^^^^^
  File "/Users/campusheilbronn/PycharmProjects/TUMDiscordBot/.venv/lib/python3.12/site-packages/aiohttp/connector.py", line 1020, in _resolve_host_with_throttle
    addrs = await self._resolver.resolve(host, port, family=self._family)
            ^^^^^^^^^^^^^^^^^^^^^^^^^^^^^^^^^^^^^^^^^^^^^^^^^^^^^^^^^^^^^
  File "/Users/campusheilbronn/PycharmProjects/TUMDiscordBot/.venv/lib/python3.12/site-packages/aiohttp/resolver.py", line 36, in resolve
    infos = await self._loop.getaddrinfo(
            ^^^^^^^^^^^^^^^^^^^^^^^^^^^^^
  File "/Library/Frameworks/Python.framework/Versions/3.12/lib/python3.12/asyncio/base_events.py", line 901, in getaddrinfo
    return await self.run_in_executor(
           ^^^^^^^^^^^^^^^^^^^^^^^^^^^
  File "/Library/Frameworks/Python.framework/Versions/3.12/lib/python3.12/concurrent/futures/thread.py", line 58, in run
    result = self.fn(*self.args, **self.kwargs)
             ^^^^^^^^^^^^^^^^^^^^^^^^^^^^^^^^^^
  File "/Library/Frameworks/Python.framework/Versions/3.12/lib/python3.12/socket.py", line 976, in getaddrinfo
    for res in _socket.getaddrinfo(host, port, family, type, proto, flags):
               ^^^^^^^^^^^^^^^^^^^^^^^^^^^^^^^^^^^^^^^^^^^^^^^^^^^^^^^^^^^
socket.gaierror: [Errno 8] nodename nor servname provided, or not known

The above exception was the direct cause of the following exception:

Traceback (most recent call last):
  File "/Users/campusheilbronn/PycharmProjects/TUMDiscordBot/.venv/lib/python3.12/site-packages/discord/client.py", line 598, in connect
    self.ws = await asyncio.wait_for(coro, timeout=60.0)
              ^^^^^^^^^^^^^^^^^^^^^^^^^^^^^^^^^^^^^^^^^^
  File "/Library/Frameworks/Python.framework/Versions/3.12/lib/python3.12/asyncio/tasks.py", line 520, in wait_for
    return await fut
           ^^^^^^^^^
  File "/Users/campusheilbronn/PycharmProjects/TUMDiscordBot/.venv/lib/python3.12/site-packages/discord/gateway.py", line 338, in from_client
    gateway = gateway or await client.http.get_gateway()
                         ^^^^^^^^^^^^^^^^^^^^^^^^^^^^^^^
  File "/Users/campusheilbronn/PycharmProjects/TUMDiscordBot/.venv/lib/python3.12/site-packages/discord/http.py", line 2999, in get_gateway
    data = await self.request(Route("GET", "/gateway"))
           ^^^^^^^^^^^^^^^^^^^^^^^^^^^^^^^^^^^^^^^^^^^^
  File "/Users/campusheilbronn/PycharmProjects/TUMDiscordBot/.venv/lib/python3.12/site-packages/discord/http.py", line 285, in request
    async with self.__session.request(
               ^^^^^^^^^^^^^^^^^^^^^^^
  File "/Users/campusheilbronn/PycharmProjects/TUMDiscordBot/.venv/lib/python3.12/site-packages/aiohttp/client.py", line 1423, in __aenter__
    self._resp: _RetType = await self._coro
                           ^^^^^^^^^^^^^^^^
  File "/Users/campusheilbronn/PycharmProjects/TUMDiscordBot/.venv/lib/python3.12/site-packages/aiohttp/client.py", line 701, in _request
    conn = await self._connector.connect(
           ^^^^^^^^^^^^^^^^^^^^^^^^^^^^^^
  File "/Users/campusheilbronn/PycharmProjects/TUMDiscordBot/.venv/lib/python3.12/site-packages/aiohttp/connector.py", line 544, in connect
    proto = await self._create_connection(req, traces, timeout)
            ^^^^^^^^^^^^^^^^^^^^^^^^^^^^^^^^^^^^^^^^^^^^^^^^^^^
  File "/Users/campusheilbronn/PycharmProjects/TUMDiscordBot/.venv/lib/python3.12/site-packages/aiohttp/connector.py", line 1050, in _create_connection
    _, proto = await self._create_direct_connection(req, traces, timeout)
               ^^^^^^^^^^^^^^^^^^^^^^^^^^^^^^^^^^^^^^^^^^^^^^^^^^^^^^^^^^
  File "/Users/campusheilbronn/PycharmProjects/TUMDiscordBot/.venv/lib/python3.12/site-packages/aiohttp/connector.py", line 1351, in _create_direct_connection
    raise ClientConnectorDNSError(req.connection_key, exc) from exc
aiohttp.client_exceptions.ClientConnectorDNSError: Cannot connect to host discord.com:443 ssl:default [nodename nor servname provided, or not known]
2025-05-05 20:49:02,705 - discord.client - ERROR - Attempting a reconnect in 1.73s
Traceback (most recent call last):
  File "/Users/campusheilbronn/PycharmProjects/TUMDiscordBot/.venv/lib/python3.12/site-packages/aiohttp/connector.py", line 1345, in _create_direct_connection
    hosts = await self._resolve_host(host, port, traces=traces)
            ^^^^^^^^^^^^^^^^^^^^^^^^^^^^^^^^^^^^^^^^^^^^^^^^^^^
  File "/Users/campusheilbronn/PycharmProjects/TUMDiscordBot/.venv/lib/python3.12/site-packages/aiohttp/connector.py", line 989, in _resolve_host
    return await asyncio.shield(resolved_host_task)
           ^^^^^^^^^^^^^^^^^^^^^^^^^^^^^^^^^^^^^^^^
  File "/Users/campusheilbronn/PycharmProjects/TUMDiscordBot/.venv/lib/python3.12/site-packages/aiohttp/connector.py", line 1020, in _resolve_host_with_throttle
    addrs = await self._resolver.resolve(host, port, family=self._family)
            ^^^^^^^^^^^^^^^^^^^^^^^^^^^^^^^^^^^^^^^^^^^^^^^^^^^^^^^^^^^^^
  File "/Users/campusheilbronn/PycharmProjects/TUMDiscordBot/.venv/lib/python3.12/site-packages/aiohttp/resolver.py", line 36, in resolve
    infos = await self._loop.getaddrinfo(
            ^^^^^^^^^^^^^^^^^^^^^^^^^^^^^
  File "/Library/Frameworks/Python.framework/Versions/3.12/lib/python3.12/asyncio/base_events.py", line 901, in getaddrinfo
    return await self.run_in_executor(
           ^^^^^^^^^^^^^^^^^^^^^^^^^^^
  File "/Library/Frameworks/Python.framework/Versions/3.12/lib/python3.12/concurrent/futures/thread.py", line 58, in run
    result = self.fn(*self.args, **self.kwargs)
             ^^^^^^^^^^^^^^^^^^^^^^^^^^^^^^^^^^
  File "/Library/Frameworks/Python.framework/Versions/3.12/lib/python3.12/socket.py", line 976, in getaddrinfo
    for res in _socket.getaddrinfo(host, port, family, type, proto, flags):
               ^^^^^^^^^^^^^^^^^^^^^^^^^^^^^^^^^^^^^^^^^^^^^^^^^^^^^^^^^^^
socket.gaierror: [Errno 8] nodename nor servname provided, or not known

The above exception was the direct cause of the following exception:

Traceback (most recent call last):
  File "/Users/campusheilbronn/PycharmProjects/TUMDiscordBot/.venv/lib/python3.12/site-packages/discord/client.py", line 598, in connect
    self.ws = await asyncio.wait_for(coro, timeout=60.0)
              ^^^^^^^^^^^^^^^^^^^^^^^^^^^^^^^^^^^^^^^^^^
  File "/Library/Frameworks/Python.framework/Versions/3.12/lib/python3.12/asyncio/tasks.py", line 520, in wait_for
    return await fut
           ^^^^^^^^^
  File "/Users/campusheilbronn/PycharmProjects/TUMDiscordBot/.venv/lib/python3.12/site-packages/discord/gateway.py", line 338, in from_client
    gateway = gateway or await client.http.get_gateway()
                         ^^^^^^^^^^^^^^^^^^^^^^^^^^^^^^^
  File "/Users/campusheilbronn/PycharmProjects/TUMDiscordBot/.venv/lib/python3.12/site-packages/discord/http.py", line 2999, in get_gateway
    data = await self.request(Route("GET", "/gateway"))
           ^^^^^^^^^^^^^^^^^^^^^^^^^^^^^^^^^^^^^^^^^^^^
  File "/Users/campusheilbronn/PycharmProjects/TUMDiscordBot/.venv/lib/python3.12/site-packages/discord/http.py", line 285, in request
    async with self.__session.request(
               ^^^^^^^^^^^^^^^^^^^^^^^
  File "/Users/campusheilbronn/PycharmProjects/TUMDiscordBot/.venv/lib/python3.12/site-packages/aiohttp/client.py", line 1423, in __aenter__
    self._resp: _RetType = await self._coro
                           ^^^^^^^^^^^^^^^^
  File "/Users/campusheilbronn/PycharmProjects/TUMDiscordBot/.venv/lib/python3.12/site-packages/aiohttp/client.py", line 701, in _request
    conn = await self._connector.connect(
           ^^^^^^^^^^^^^^^^^^^^^^^^^^^^^^
  File "/Users/campusheilbronn/PycharmProjects/TUMDiscordBot/.venv/lib/python3.12/site-packages/aiohttp/connector.py", line 544, in connect
    proto = await self._create_connection(req, traces, timeout)
            ^^^^^^^^^^^^^^^^^^^^^^^^^^^^^^^^^^^^^^^^^^^^^^^^^^^
  File "/Users/campusheilbronn/PycharmProjects/TUMDiscordBot/.venv/lib/python3.12/site-packages/aiohttp/connector.py", line 1050, in _create_connection
    _, proto = await self._create_direct_connection(req, traces, timeout)
               ^^^^^^^^^^^^^^^^^^^^^^^^^^^^^^^^^^^^^^^^^^^^^^^^^^^^^^^^^^
  File "/Users/campusheilbronn/PycharmProjects/TUMDiscordBot/.venv/lib/python3.12/site-packages/aiohttp/connector.py", line 1351, in _create_direct_connection
    raise ClientConnectorDNSError(req.connection_key, exc) from exc
aiohttp.client_exceptions.ClientConnectorDNSError: Cannot connect to host discord.com:443 ssl:default [nodename nor servname provided, or not known]
2025-05-05 20:49:04,444 - discord.client - ERROR - Attempting a reconnect in 37.70s
Traceback (most recent call last):
  File "/Users/campusheilbronn/PycharmProjects/TUMDiscordBot/.venv/lib/python3.12/site-packages/aiohttp/connector.py", line 1345, in _create_direct_connection
    hosts = await self._resolve_host(host, port, traces=traces)
            ^^^^^^^^^^^^^^^^^^^^^^^^^^^^^^^^^^^^^^^^^^^^^^^^^^^
  File "/Users/campusheilbronn/PycharmProjects/TUMDiscordBot/.venv/lib/python3.12/site-packages/aiohttp/connector.py", line 989, in _resolve_host
    return await asyncio.shield(resolved_host_task)
           ^^^^^^^^^^^^^^^^^^^^^^^^^^^^^^^^^^^^^^^^
  File "/Users/campusheilbronn/PycharmProjects/TUMDiscordBot/.venv/lib/python3.12/site-packages/aiohttp/connector.py", line 1020, in _resolve_host_with_throttle
    addrs = await self._resolver.resolve(host, port, family=self._family)
            ^^^^^^^^^^^^^^^^^^^^^^^^^^^^^^^^^^^^^^^^^^^^^^^^^^^^^^^^^^^^^
  File "/Users/campusheilbronn/PycharmProjects/TUMDiscordBot/.venv/lib/python3.12/site-packages/aiohttp/resolver.py", line 36, in resolve
    infos = await self._loop.getaddrinfo(
            ^^^^^^^^^^^^^^^^^^^^^^^^^^^^^
  File "/Library/Frameworks/Python.framework/Versions/3.12/lib/python3.12/asyncio/base_events.py", line 901, in getaddrinfo
    return await self.run_in_executor(
           ^^^^^^^^^^^^^^^^^^^^^^^^^^^
  File "/Library/Frameworks/Python.framework/Versions/3.12/lib/python3.12/concurrent/futures/thread.py", line 58, in run
    result = self.fn(*self.args, **self.kwargs)
             ^^^^^^^^^^^^^^^^^^^^^^^^^^^^^^^^^^
  File "/Library/Frameworks/Python.framework/Versions/3.12/lib/python3.12/socket.py", line 976, in getaddrinfo
    for res in _socket.getaddrinfo(host, port, family, type, proto, flags):
               ^^^^^^^^^^^^^^^^^^^^^^^^^^^^^^^^^^^^^^^^^^^^^^^^^^^^^^^^^^^
socket.gaierror: [Errno 8] nodename nor servname provided, or not known

The above exception was the direct cause of the following exception:

Traceback (most recent call last):
  File "/Users/campusheilbronn/PycharmProjects/TUMDiscordBot/.venv/lib/python3.12/site-packages/discord/client.py", line 598, in connect
    self.ws = await asyncio.wait_for(coro, timeout=60.0)
              ^^^^^^^^^^^^^^^^^^^^^^^^^^^^^^^^^^^^^^^^^^
  File "/Library/Frameworks/Python.framework/Versions/3.12/lib/python3.12/asyncio/tasks.py", line 520, in wait_for
    return await fut
           ^^^^^^^^^
  File "/Users/campusheilbronn/PycharmProjects/TUMDiscordBot/.venv/lib/python3.12/site-packages/discord/gateway.py", line 338, in from_client
    gateway = gateway or await client.http.get_gateway()
                         ^^^^^^^^^^^^^^^^^^^^^^^^^^^^^^^
  File "/Users/campusheilbronn/PycharmProjects/TUMDiscordBot/.venv/lib/python3.12/site-packages/discord/http.py", line 2999, in get_gateway
    data = await self.request(Route("GET", "/gateway"))
           ^^^^^^^^^^^^^^^^^^^^^^^^^^^^^^^^^^^^^^^^^^^^
  File "/Users/campusheilbronn/PycharmProjects/TUMDiscordBot/.venv/lib/python3.12/site-packages/discord/http.py", line 285, in request
    async with self.__session.request(
               ^^^^^^^^^^^^^^^^^^^^^^^
  File "/Users/campusheilbronn/PycharmProjects/TUMDiscordBot/.venv/lib/python3.12/site-packages/aiohttp/client.py", line 1423, in __aenter__
    self._resp: _RetType = await self._coro
                           ^^^^^^^^^^^^^^^^
  File "/Users/campusheilbronn/PycharmProjects/TUMDiscordBot/.venv/lib/python3.12/site-packages/aiohttp/client.py", line 701, in _request
    conn = await self._connector.connect(
           ^^^^^^^^^^^^^^^^^^^^^^^^^^^^^^
  File "/Users/campusheilbronn/PycharmProjects/TUMDiscordBot/.venv/lib/python3.12/site-packages/aiohttp/connector.py", line 544, in connect
    proto = await self._create_connection(req, traces, timeout)
            ^^^^^^^^^^^^^^^^^^^^^^^^^^^^^^^^^^^^^^^^^^^^^^^^^^^
  File "/Users/campusheilbronn/PycharmProjects/TUMDiscordBot/.venv/lib/python3.12/site-packages/aiohttp/connector.py", line 1050, in _create_connection
    _, proto = await self._create_direct_connection(req, traces, timeout)
               ^^^^^^^^^^^^^^^^^^^^^^^^^^^^^^^^^^^^^^^^^^^^^^^^^^^^^^^^^^
  File "/Users/campusheilbronn/PycharmProjects/TUMDiscordBot/.venv/lib/python3.12/site-packages/aiohttp/connector.py", line 1351, in _create_direct_connection
    raise ClientConnectorDNSError(req.connection_key, exc) from exc
aiohttp.client_exceptions.ClientConnectorDNSError: Cannot connect to host discord.com:443 ssl:default [nodename nor servname provided, or not known]
2025-05-05 20:53:02,497 - discord.client - ERROR - Attempting a reconnect in 39.51s
Traceback (most recent call last):
  File "/Users/campusheilbronn/PycharmProjects/TUMDiscordBot/.venv/lib/python3.12/site-packages/aiohttp/connector.py", line 1345, in _create_direct_connection
    hosts = await self._resolve_host(host, port, traces=traces)
            ^^^^^^^^^^^^^^^^^^^^^^^^^^^^^^^^^^^^^^^^^^^^^^^^^^^
  File "/Users/campusheilbronn/PycharmProjects/TUMDiscordBot/.venv/lib/python3.12/site-packages/aiohttp/connector.py", line 989, in _resolve_host
    return await asyncio.shield(resolved_host_task)
           ^^^^^^^^^^^^^^^^^^^^^^^^^^^^^^^^^^^^^^^^
  File "/Users/campusheilbronn/PycharmProjects/TUMDiscordBot/.venv/lib/python3.12/site-packages/aiohttp/connector.py", line 1020, in _resolve_host_with_throttle
    addrs = await self._resolver.resolve(host, port, family=self._family)
            ^^^^^^^^^^^^^^^^^^^^^^^^^^^^^^^^^^^^^^^^^^^^^^^^^^^^^^^^^^^^^
  File "/Users/campusheilbronn/PycharmProjects/TUMDiscordBot/.venv/lib/python3.12/site-packages/aiohttp/resolver.py", line 36, in resolve
    infos = await self._loop.getaddrinfo(
            ^^^^^^^^^^^^^^^^^^^^^^^^^^^^^
  File "/Library/Frameworks/Python.framework/Versions/3.12/lib/python3.12/asyncio/base_events.py", line 901, in getaddrinfo
    return await self.run_in_executor(
           ^^^^^^^^^^^^^^^^^^^^^^^^^^^
  File "/Library/Frameworks/Python.framework/Versions/3.12/lib/python3.12/concurrent/futures/thread.py", line 58, in run
    result = self.fn(*self.args, **self.kwargs)
             ^^^^^^^^^^^^^^^^^^^^^^^^^^^^^^^^^^
  File "/Library/Frameworks/Python.framework/Versions/3.12/lib/python3.12/socket.py", line 976, in getaddrinfo
    for res in _socket.getaddrinfo(host, port, family, type, proto, flags):
               ^^^^^^^^^^^^^^^^^^^^^^^^^^^^^^^^^^^^^^^^^^^^^^^^^^^^^^^^^^^
socket.gaierror: [Errno 8] nodename nor servname provided, or not known

The above exception was the direct cause of the following exception:

Traceback (most recent call last):
  File "/Users/campusheilbronn/PycharmProjects/TUMDiscordBot/.venv/lib/python3.12/site-packages/discord/client.py", line 598, in connect
    self.ws = await asyncio.wait_for(coro, timeout=60.0)
              ^^^^^^^^^^^^^^^^^^^^^^^^^^^^^^^^^^^^^^^^^^
  File "/Library/Frameworks/Python.framework/Versions/3.12/lib/python3.12/asyncio/tasks.py", line 520, in wait_for
    return await fut
           ^^^^^^^^^
  File "/Users/campusheilbronn/PycharmProjects/TUMDiscordBot/.venv/lib/python3.12/site-packages/discord/gateway.py", line 338, in from_client
    gateway = gateway or await client.http.get_gateway()
                         ^^^^^^^^^^^^^^^^^^^^^^^^^^^^^^^
  File "/Users/campusheilbronn/PycharmProjects/TUMDiscordBot/.venv/lib/python3.12/site-packages/discord/http.py", line 2999, in get_gateway
    data = await self.request(Route("GET", "/gateway"))
           ^^^^^^^^^^^^^^^^^^^^^^^^^^^^^^^^^^^^^^^^^^^^
  File "/Users/campusheilbronn/PycharmProjects/TUMDiscordBot/.venv/lib/python3.12/site-packages/discord/http.py", line 285, in request
    async with self.__session.request(
               ^^^^^^^^^^^^^^^^^^^^^^^
  File "/Users/campusheilbronn/PycharmProjects/TUMDiscordBot/.venv/lib/python3.12/site-packages/aiohttp/client.py", line 1423, in __aenter__
    self._resp: _RetType = await self._coro
                           ^^^^^^^^^^^^^^^^
  File "/Users/campusheilbronn/PycharmProjects/TUMDiscordBot/.venv/lib/python3.12/site-packages/aiohttp/client.py", line 701, in _request
    conn = await self._connector.connect(
           ^^^^^^^^^^^^^^^^^^^^^^^^^^^^^^
  File "/Users/campusheilbronn/PycharmProjects/TUMDiscordBot/.venv/lib/python3.12/site-packages/aiohttp/connector.py", line 544, in connect
    proto = await self._create_connection(req, traces, timeout)
            ^^^^^^^^^^^^^^^^^^^^^^^^^^^^^^^^^^^^^^^^^^^^^^^^^^^
  File "/Users/campusheilbronn/PycharmProjects/TUMDiscordBot/.venv/lib/python3.12/site-packages/aiohttp/connector.py", line 1050, in _create_connection
    _, proto = await self._create_direct_connection(req, traces, timeout)
               ^^^^^^^^^^^^^^^^^^^^^^^^^^^^^^^^^^^^^^^^^^^^^^^^^^^^^^^^^^
  File "/Users/campusheilbronn/PycharmProjects/TUMDiscordBot/.venv/lib/python3.12/site-packages/aiohttp/connector.py", line 1351, in _create_direct_connection
    raise ClientConnectorDNSError(req.connection_key, exc) from exc
aiohttp.client_exceptions.ClientConnectorDNSError: Cannot connect to host discord.com:443 ssl:default [nodename nor servname provided, or not known]
2025-05-05 20:56:19,180 - discord.client - ERROR - Attempting a reconnect in 69.33s
Traceback (most recent call last):
  File "/Users/campusheilbronn/PycharmProjects/TUMDiscordBot/.venv/lib/python3.12/site-packages/aiohttp/connector.py", line 1345, in _create_direct_connection
    hosts = await self._resolve_host(host, port, traces=traces)
            ^^^^^^^^^^^^^^^^^^^^^^^^^^^^^^^^^^^^^^^^^^^^^^^^^^^
  File "/Users/campusheilbronn/PycharmProjects/TUMDiscordBot/.venv/lib/python3.12/site-packages/aiohttp/connector.py", line 989, in _resolve_host
    return await asyncio.shield(resolved_host_task)
           ^^^^^^^^^^^^^^^^^^^^^^^^^^^^^^^^^^^^^^^^
  File "/Users/campusheilbronn/PycharmProjects/TUMDiscordBot/.venv/lib/python3.12/site-packages/aiohttp/connector.py", line 1020, in _resolve_host_with_throttle
    addrs = await self._resolver.resolve(host, port, family=self._family)
            ^^^^^^^^^^^^^^^^^^^^^^^^^^^^^^^^^^^^^^^^^^^^^^^^^^^^^^^^^^^^^
  File "/Users/campusheilbronn/PycharmProjects/TUMDiscordBot/.venv/lib/python3.12/site-packages/aiohttp/resolver.py", line 36, in resolve
    infos = await self._loop.getaddrinfo(
            ^^^^^^^^^^^^^^^^^^^^^^^^^^^^^
  File "/Library/Frameworks/Python.framework/Versions/3.12/lib/python3.12/asyncio/base_events.py", line 901, in getaddrinfo
    return await self.run_in_executor(
           ^^^^^^^^^^^^^^^^^^^^^^^^^^^
  File "/Library/Frameworks/Python.framework/Versions/3.12/lib/python3.12/concurrent/futures/thread.py", line 58, in run
    result = self.fn(*self.args, **self.kwargs)
             ^^^^^^^^^^^^^^^^^^^^^^^^^^^^^^^^^^
  File "/Library/Frameworks/Python.framework/Versions/3.12/lib/python3.12/socket.py", line 976, in getaddrinfo
    for res in _socket.getaddrinfo(host, port, family, type, proto, flags):
               ^^^^^^^^^^^^^^^^^^^^^^^^^^^^^^^^^^^^^^^^^^^^^^^^^^^^^^^^^^^
socket.gaierror: [Errno 8] nodename nor servname provided, or not known

The above exception was the direct cause of the following exception:

Traceback (most recent call last):
  File "/Users/campusheilbronn/PycharmProjects/TUMDiscordBot/.venv/lib/python3.12/site-packages/discord/client.py", line 598, in connect
    self.ws = await asyncio.wait_for(coro, timeout=60.0)
              ^^^^^^^^^^^^^^^^^^^^^^^^^^^^^^^^^^^^^^^^^^
  File "/Library/Frameworks/Python.framework/Versions/3.12/lib/python3.12/asyncio/tasks.py", line 520, in wait_for
    return await fut
           ^^^^^^^^^
  File "/Users/campusheilbronn/PycharmProjects/TUMDiscordBot/.venv/lib/python3.12/site-packages/discord/gateway.py", line 338, in from_client
    gateway = gateway or await client.http.get_gateway()
                         ^^^^^^^^^^^^^^^^^^^^^^^^^^^^^^^
  File "/Users/campusheilbronn/PycharmProjects/TUMDiscordBot/.venv/lib/python3.12/site-packages/discord/http.py", line 2999, in get_gateway
    data = await self.request(Route("GET", "/gateway"))
           ^^^^^^^^^^^^^^^^^^^^^^^^^^^^^^^^^^^^^^^^^^^^
  File "/Users/campusheilbronn/PycharmProjects/TUMDiscordBot/.venv/lib/python3.12/site-packages/discord/http.py", line 285, in request
    async with self.__session.request(
               ^^^^^^^^^^^^^^^^^^^^^^^
  File "/Users/campusheilbronn/PycharmProjects/TUMDiscordBot/.venv/lib/python3.12/site-packages/aiohttp/client.py", line 1423, in __aenter__
    self._resp: _RetType = await self._coro
                           ^^^^^^^^^^^^^^^^
  File "/Users/campusheilbronn/PycharmProjects/TUMDiscordBot/.venv/lib/python3.12/site-packages/aiohttp/client.py", line 701, in _request
    conn = await self._connector.connect(
           ^^^^^^^^^^^^^^^^^^^^^^^^^^^^^^
  File "/Users/campusheilbronn/PycharmProjects/TUMDiscordBot/.venv/lib/python3.12/site-packages/aiohttp/connector.py", line 544, in connect
    proto = await self._create_connection(req, traces, timeout)
            ^^^^^^^^^^^^^^^^^^^^^^^^^^^^^^^^^^^^^^^^^^^^^^^^^^^
  File "/Users/campusheilbronn/PycharmProjects/TUMDiscordBot/.venv/lib/python3.12/site-packages/aiohttp/connector.py", line 1050, in _create_connection
    _, proto = await self._create_direct_connection(req, traces, timeout)
               ^^^^^^^^^^^^^^^^^^^^^^^^^^^^^^^^^^^^^^^^^^^^^^^^^^^^^^^^^^
  File "/Users/campusheilbronn/PycharmProjects/TUMDiscordBot/.venv/lib/python3.12/site-packages/aiohttp/connector.py", line 1351, in _create_direct_connection
    raise ClientConnectorDNSError(req.connection_key, exc) from exc
aiohttp.client_exceptions.ClientConnectorDNSError: Cannot connect to host discord.com:443 ssl:default [nodename nor servname provided, or not known]
2025-05-05 21:02:06,376 - discord.client - ERROR - Attempting a reconnect in 198.08s
Traceback (most recent call last):
  File "/Users/campusheilbronn/PycharmProjects/TUMDiscordBot/.venv/lib/python3.12/site-packages/aiohttp/connector.py", line 1345, in _create_direct_connection
    hosts = await self._resolve_host(host, port, traces=traces)
            ^^^^^^^^^^^^^^^^^^^^^^^^^^^^^^^^^^^^^^^^^^^^^^^^^^^
  File "/Users/campusheilbronn/PycharmProjects/TUMDiscordBot/.venv/lib/python3.12/site-packages/aiohttp/connector.py", line 989, in _resolve_host
    return await asyncio.shield(resolved_host_task)
           ^^^^^^^^^^^^^^^^^^^^^^^^^^^^^^^^^^^^^^^^
  File "/Users/campusheilbronn/PycharmProjects/TUMDiscordBot/.venv/lib/python3.12/site-packages/aiohttp/connector.py", line 1020, in _resolve_host_with_throttle
    addrs = await self._resolver.resolve(host, port, family=self._family)
            ^^^^^^^^^^^^^^^^^^^^^^^^^^^^^^^^^^^^^^^^^^^^^^^^^^^^^^^^^^^^^
  File "/Users/campusheilbronn/PycharmProjects/TUMDiscordBot/.venv/lib/python3.12/site-packages/aiohttp/resolver.py", line 36, in resolve
    infos = await self._loop.getaddrinfo(
            ^^^^^^^^^^^^^^^^^^^^^^^^^^^^^
  File "/Library/Frameworks/Python.framework/Versions/3.12/lib/python3.12/asyncio/base_events.py", line 901, in getaddrinfo
    return await self.run_in_executor(
           ^^^^^^^^^^^^^^^^^^^^^^^^^^^
  File "/Library/Frameworks/Python.framework/Versions/3.12/lib/python3.12/concurrent/futures/thread.py", line 58, in run
    result = self.fn(*self.args, **self.kwargs)
             ^^^^^^^^^^^^^^^^^^^^^^^^^^^^^^^^^^
  File "/Library/Frameworks/Python.framework/Versions/3.12/lib/python3.12/socket.py", line 976, in getaddrinfo
    for res in _socket.getaddrinfo(host, port, family, type, proto, flags):
               ^^^^^^^^^^^^^^^^^^^^^^^^^^^^^^^^^^^^^^^^^^^^^^^^^^^^^^^^^^^
socket.gaierror: [Errno 8] nodename nor servname provided, or not known

The above exception was the direct cause of the following exception:

Traceback (most recent call last):
  File "/Users/campusheilbronn/PycharmProjects/TUMDiscordBot/.venv/lib/python3.12/site-packages/discord/client.py", line 598, in connect
    self.ws = await asyncio.wait_for(coro, timeout=60.0)
              ^^^^^^^^^^^^^^^^^^^^^^^^^^^^^^^^^^^^^^^^^^
  File "/Library/Frameworks/Python.framework/Versions/3.12/lib/python3.12/asyncio/tasks.py", line 520, in wait_for
    return await fut
           ^^^^^^^^^
  File "/Users/campusheilbronn/PycharmProjects/TUMDiscordBot/.venv/lib/python3.12/site-packages/discord/gateway.py", line 338, in from_client
    gateway = gateway or await client.http.get_gateway()
                         ^^^^^^^^^^^^^^^^^^^^^^^^^^^^^^^
  File "/Users/campusheilbronn/PycharmProjects/TUMDiscordBot/.venv/lib/python3.12/site-packages/discord/http.py", line 2999, in get_gateway
    data = await self.request(Route("GET", "/gateway"))
           ^^^^^^^^^^^^^^^^^^^^^^^^^^^^^^^^^^^^^^^^^^^^
  File "/Users/campusheilbronn/PycharmProjects/TUMDiscordBot/.venv/lib/python3.12/site-packages/discord/http.py", line 285, in request
    async with self.__session.request(
               ^^^^^^^^^^^^^^^^^^^^^^^
  File "/Users/campusheilbronn/PycharmProjects/TUMDiscordBot/.venv/lib/python3.12/site-packages/aiohttp/client.py", line 1423, in __aenter__
    self._resp: _RetType = await self._coro
                           ^^^^^^^^^^^^^^^^
  File "/Users/campusheilbronn/PycharmProjects/TUMDiscordBot/.venv/lib/python3.12/site-packages/aiohttp/client.py", line 701, in _request
    conn = await self._connector.connect(
           ^^^^^^^^^^^^^^^^^^^^^^^^^^^^^^
  File "/Users/campusheilbronn/PycharmProjects/TUMDiscordBot/.venv/lib/python3.12/site-packages/aiohttp/connector.py", line 544, in connect
    proto = await self._create_connection(req, traces, timeout)
            ^^^^^^^^^^^^^^^^^^^^^^^^^^^^^^^^^^^^^^^^^^^^^^^^^^^
  File "/Users/campusheilbronn/PycharmProjects/TUMDiscordBot/.venv/lib/python3.12/site-packages/aiohttp/connector.py", line 1050, in _create_connection
    _, proto = await self._create_direct_connection(req, traces, timeout)
               ^^^^^^^^^^^^^^^^^^^^^^^^^^^^^^^^^^^^^^^^^^^^^^^^^^^^^^^^^^
  File "/Users/campusheilbronn/PycharmProjects/TUMDiscordBot/.venv/lib/python3.12/site-packages/aiohttp/connector.py", line 1351, in _create_direct_connection
    raise ClientConnectorDNSError(req.connection_key, exc) from exc
aiohttp.client_exceptions.ClientConnectorDNSError: Cannot connect to host discord.com:443 ssl:default [nodename nor servname provided, or not known]
2025-05-05 21:20:37,636 - discord.client - ERROR - Attempting a reconnect in 61.30s
Traceback (most recent call last):
  File "/Users/campusheilbronn/PycharmProjects/TUMDiscordBot/.venv/lib/python3.12/site-packages/aiohttp/connector.py", line 1345, in _create_direct_connection
    hosts = await self._resolve_host(host, port, traces=traces)
            ^^^^^^^^^^^^^^^^^^^^^^^^^^^^^^^^^^^^^^^^^^^^^^^^^^^
  File "/Users/campusheilbronn/PycharmProjects/TUMDiscordBot/.venv/lib/python3.12/site-packages/aiohttp/connector.py", line 989, in _resolve_host
    return await asyncio.shield(resolved_host_task)
           ^^^^^^^^^^^^^^^^^^^^^^^^^^^^^^^^^^^^^^^^
  File "/Users/campusheilbronn/PycharmProjects/TUMDiscordBot/.venv/lib/python3.12/site-packages/aiohttp/connector.py", line 1020, in _resolve_host_with_throttle
    addrs = await self._resolver.resolve(host, port, family=self._family)
            ^^^^^^^^^^^^^^^^^^^^^^^^^^^^^^^^^^^^^^^^^^^^^^^^^^^^^^^^^^^^^
  File "/Users/campusheilbronn/PycharmProjects/TUMDiscordBot/.venv/lib/python3.12/site-packages/aiohttp/resolver.py", line 36, in resolve
    infos = await self._loop.getaddrinfo(
            ^^^^^^^^^^^^^^^^^^^^^^^^^^^^^
  File "/Library/Frameworks/Python.framework/Versions/3.12/lib/python3.12/asyncio/base_events.py", line 901, in getaddrinfo
    return await self.run_in_executor(
           ^^^^^^^^^^^^^^^^^^^^^^^^^^^
  File "/Library/Frameworks/Python.framework/Versions/3.12/lib/python3.12/concurrent/futures/thread.py", line 58, in run
    result = self.fn(*self.args, **self.kwargs)
             ^^^^^^^^^^^^^^^^^^^^^^^^^^^^^^^^^^
  File "/Library/Frameworks/Python.framework/Versions/3.12/lib/python3.12/socket.py", line 976, in getaddrinfo
    for res in _socket.getaddrinfo(host, port, family, type, proto, flags):
               ^^^^^^^^^^^^^^^^^^^^^^^^^^^^^^^^^^^^^^^^^^^^^^^^^^^^^^^^^^^
socket.gaierror: [Errno 8] nodename nor servname provided, or not known

The above exception was the direct cause of the following exception:

Traceback (most recent call last):
  File "/Users/campusheilbronn/PycharmProjects/TUMDiscordBot/.venv/lib/python3.12/site-packages/discord/client.py", line 598, in connect
    self.ws = await asyncio.wait_for(coro, timeout=60.0)
              ^^^^^^^^^^^^^^^^^^^^^^^^^^^^^^^^^^^^^^^^^^
  File "/Library/Frameworks/Python.framework/Versions/3.12/lib/python3.12/asyncio/tasks.py", line 520, in wait_for
    return await fut
           ^^^^^^^^^
  File "/Users/campusheilbronn/PycharmProjects/TUMDiscordBot/.venv/lib/python3.12/site-packages/discord/gateway.py", line 338, in from_client
    gateway = gateway or await client.http.get_gateway()
                         ^^^^^^^^^^^^^^^^^^^^^^^^^^^^^^^
  File "/Users/campusheilbronn/PycharmProjects/TUMDiscordBot/.venv/lib/python3.12/site-packages/discord/http.py", line 2999, in get_gateway
    data = await self.request(Route("GET", "/gateway"))
           ^^^^^^^^^^^^^^^^^^^^^^^^^^^^^^^^^^^^^^^^^^^^
  File "/Users/campusheilbronn/PycharmProjects/TUMDiscordBot/.venv/lib/python3.12/site-packages/discord/http.py", line 285, in request
    async with self.__session.request(
               ^^^^^^^^^^^^^^^^^^^^^^^
  File "/Users/campusheilbronn/PycharmProjects/TUMDiscordBot/.venv/lib/python3.12/site-packages/aiohttp/client.py", line 1423, in __aenter__
    self._resp: _RetType = await self._coro
                           ^^^^^^^^^^^^^^^^
  File "/Users/campusheilbronn/PycharmProjects/TUMDiscordBot/.venv/lib/python3.12/site-packages/aiohttp/client.py", line 701, in _request
    conn = await self._connector.connect(
           ^^^^^^^^^^^^^^^^^^^^^^^^^^^^^^
  File "/Users/campusheilbronn/PycharmProjects/TUMDiscordBot/.venv/lib/python3.12/site-packages/aiohttp/connector.py", line 544, in connect
    proto = await self._create_connection(req, traces, timeout)
            ^^^^^^^^^^^^^^^^^^^^^^^^^^^^^^^^^^^^^^^^^^^^^^^^^^^
  File "/Users/campusheilbronn/PycharmProjects/TUMDiscordBot/.venv/lib/python3.12/site-packages/aiohttp/connector.py", line 1050, in _create_connection
    _, proto = await self._create_direct_connection(req, traces, timeout)
               ^^^^^^^^^^^^^^^^^^^^^^^^^^^^^^^^^^^^^^^^^^^^^^^^^^^^^^^^^^
  File "/Users/campusheilbronn/PycharmProjects/TUMDiscordBot/.venv/lib/python3.12/site-packages/aiohttp/connector.py", line 1351, in _create_direct_connection
    raise ClientConnectorDNSError(req.connection_key, exc) from exc
aiohttp.client_exceptions.ClientConnectorDNSError: Cannot connect to host discord.com:443 ssl:default [nodename nor servname provided, or not known]
2025-05-05 21:25:41,737 - discord.client - ERROR - Attempting a reconnect in 593.07s
Traceback (most recent call last):
  File "/Users/campusheilbronn/PycharmProjects/TUMDiscordBot/.venv/lib/python3.12/site-packages/aiohttp/connector.py", line 1345, in _create_direct_connection
    hosts = await self._resolve_host(host, port, traces=traces)
            ^^^^^^^^^^^^^^^^^^^^^^^^^^^^^^^^^^^^^^^^^^^^^^^^^^^
  File "/Users/campusheilbronn/PycharmProjects/TUMDiscordBot/.venv/lib/python3.12/site-packages/aiohttp/connector.py", line 989, in _resolve_host
    return await asyncio.shield(resolved_host_task)
           ^^^^^^^^^^^^^^^^^^^^^^^^^^^^^^^^^^^^^^^^
  File "/Users/campusheilbronn/PycharmProjects/TUMDiscordBot/.venv/lib/python3.12/site-packages/aiohttp/connector.py", line 1020, in _resolve_host_with_throttle
    addrs = await self._resolver.resolve(host, port, family=self._family)
            ^^^^^^^^^^^^^^^^^^^^^^^^^^^^^^^^^^^^^^^^^^^^^^^^^^^^^^^^^^^^^
  File "/Users/campusheilbronn/PycharmProjects/TUMDiscordBot/.venv/lib/python3.12/site-packages/aiohttp/resolver.py", line 36, in resolve
    infos = await self._loop.getaddrinfo(
            ^^^^^^^^^^^^^^^^^^^^^^^^^^^^^
  File "/Library/Frameworks/Python.framework/Versions/3.12/lib/python3.12/asyncio/base_events.py", line 901, in getaddrinfo
    return await self.run_in_executor(
           ^^^^^^^^^^^^^^^^^^^^^^^^^^^
  File "/Library/Frameworks/Python.framework/Versions/3.12/lib/python3.12/concurrent/futures/thread.py", line 58, in run
    result = self.fn(*self.args, **self.kwargs)
             ^^^^^^^^^^^^^^^^^^^^^^^^^^^^^^^^^^
  File "/Library/Frameworks/Python.framework/Versions/3.12/lib/python3.12/socket.py", line 976, in getaddrinfo
    for res in _socket.getaddrinfo(host, port, family, type, proto, flags):
               ^^^^^^^^^^^^^^^^^^^^^^^^^^^^^^^^^^^^^^^^^^^^^^^^^^^^^^^^^^^
socket.gaierror: [Errno 8] nodename nor servname provided, or not known

The above exception was the direct cause of the following exception:

Traceback (most recent call last):
  File "/Users/campusheilbronn/PycharmProjects/TUMDiscordBot/.venv/lib/python3.12/site-packages/discord/client.py", line 598, in connect
    self.ws = await asyncio.wait_for(coro, timeout=60.0)
              ^^^^^^^^^^^^^^^^^^^^^^^^^^^^^^^^^^^^^^^^^^
  File "/Library/Frameworks/Python.framework/Versions/3.12/lib/python3.12/asyncio/tasks.py", line 520, in wait_for
    return await fut
           ^^^^^^^^^
  File "/Users/campusheilbronn/PycharmProjects/TUMDiscordBot/.venv/lib/python3.12/site-packages/discord/gateway.py", line 338, in from_client
    gateway = gateway or await client.http.get_gateway()
                         ^^^^^^^^^^^^^^^^^^^^^^^^^^^^^^^
  File "/Users/campusheilbronn/PycharmProjects/TUMDiscordBot/.venv/lib/python3.12/site-packages/discord/http.py", line 2999, in get_gateway
    data = await self.request(Route("GET", "/gateway"))
           ^^^^^^^^^^^^^^^^^^^^^^^^^^^^^^^^^^^^^^^^^^^^
  File "/Users/campusheilbronn/PycharmProjects/TUMDiscordBot/.venv/lib/python3.12/site-packages/discord/http.py", line 285, in request
    async with self.__session.request(
               ^^^^^^^^^^^^^^^^^^^^^^^
  File "/Users/campusheilbronn/PycharmProjects/TUMDiscordBot/.venv/lib/python3.12/site-packages/aiohttp/client.py", line 1423, in __aenter__
    self._resp: _RetType = await self._coro
                           ^^^^^^^^^^^^^^^^
  File "/Users/campusheilbronn/PycharmProjects/TUMDiscordBot/.venv/lib/python3.12/site-packages/aiohttp/client.py", line 701, in _request
    conn = await self._connector.connect(
           ^^^^^^^^^^^^^^^^^^^^^^^^^^^^^^
  File "/Users/campusheilbronn/PycharmProjects/TUMDiscordBot/.venv/lib/python3.12/site-packages/aiohttp/connector.py", line 544, in connect
    proto = await self._create_connection(req, traces, timeout)
            ^^^^^^^^^^^^^^^^^^^^^^^^^^^^^^^^^^^^^^^^^^^^^^^^^^^
  File "/Users/campusheilbronn/PycharmProjects/TUMDiscordBot/.venv/lib/python3.12/site-packages/aiohttp/connector.py", line 1050, in _create_connection
    _, proto = await self._create_direct_connection(req, traces, timeout)
               ^^^^^^^^^^^^^^^^^^^^^^^^^^^^^^^^^^^^^^^^^^^^^^^^^^^^^^^^^^
  File "/Users/campusheilbronn/PycharmProjects/TUMDiscordBot/.venv/lib/python3.12/site-packages/aiohttp/connector.py", line 1351, in _create_direct_connection
    raise ClientConnectorDNSError(req.connection_key, exc) from exc
aiohttp.client_exceptions.ClientConnectorDNSError: Cannot connect to host discord.com:443 ssl:default [nodename nor servname provided, or not known]
2025-05-05 22:18:25,795 - discord.client - ERROR - Attempting a reconnect in 1015.27s
Traceback (most recent call last):
  File "/Users/campusheilbronn/PycharmProjects/TUMDiscordBot/.venv/lib/python3.12/site-packages/aiohttp/connector.py", line 1345, in _create_direct_connection
    hosts = await self._resolve_host(host, port, traces=traces)
            ^^^^^^^^^^^^^^^^^^^^^^^^^^^^^^^^^^^^^^^^^^^^^^^^^^^
  File "/Users/campusheilbronn/PycharmProjects/TUMDiscordBot/.venv/lib/python3.12/site-packages/aiohttp/connector.py", line 989, in _resolve_host
    return await asyncio.shield(resolved_host_task)
           ^^^^^^^^^^^^^^^^^^^^^^^^^^^^^^^^^^^^^^^^
  File "/Users/campusheilbronn/PycharmProjects/TUMDiscordBot/.venv/lib/python3.12/site-packages/aiohttp/connector.py", line 1020, in _resolve_host_with_throttle
    addrs = await self._resolver.resolve(host, port, family=self._family)
            ^^^^^^^^^^^^^^^^^^^^^^^^^^^^^^^^^^^^^^^^^^^^^^^^^^^^^^^^^^^^^
  File "/Users/campusheilbronn/PycharmProjects/TUMDiscordBot/.venv/lib/python3.12/site-packages/aiohttp/resolver.py", line 36, in resolve
    infos = await self._loop.getaddrinfo(
            ^^^^^^^^^^^^^^^^^^^^^^^^^^^^^
  File "/Library/Frameworks/Python.framework/Versions/3.12/lib/python3.12/asyncio/base_events.py", line 901, in getaddrinfo
    return await self.run_in_executor(
           ^^^^^^^^^^^^^^^^^^^^^^^^^^^
  File "/Library/Frameworks/Python.framework/Versions/3.12/lib/python3.12/concurrent/futures/thread.py", line 58, in run
    result = self.fn(*self.args, **self.kwargs)
             ^^^^^^^^^^^^^^^^^^^^^^^^^^^^^^^^^^
  File "/Library/Frameworks/Python.framework/Versions/3.12/lib/python3.12/socket.py", line 976, in getaddrinfo
    for res in _socket.getaddrinfo(host, port, family, type, proto, flags):
               ^^^^^^^^^^^^^^^^^^^^^^^^^^^^^^^^^^^^^^^^^^^^^^^^^^^^^^^^^^^
socket.gaierror: [Errno 8] nodename nor servname provided, or not known

The above exception was the direct cause of the following exception:

Traceback (most recent call last):
  File "/Users/campusheilbronn/PycharmProjects/TUMDiscordBot/.venv/lib/python3.12/site-packages/discord/client.py", line 598, in connect
    self.ws = await asyncio.wait_for(coro, timeout=60.0)
              ^^^^^^^^^^^^^^^^^^^^^^^^^^^^^^^^^^^^^^^^^^
  File "/Library/Frameworks/Python.framework/Versions/3.12/lib/python3.12/asyncio/tasks.py", line 520, in wait_for
    return await fut
           ^^^^^^^^^
  File "/Users/campusheilbronn/PycharmProjects/TUMDiscordBot/.venv/lib/python3.12/site-packages/discord/gateway.py", line 338, in from_client
    gateway = gateway or await client.http.get_gateway()
                         ^^^^^^^^^^^^^^^^^^^^^^^^^^^^^^^
  File "/Users/campusheilbronn/PycharmProjects/TUMDiscordBot/.venv/lib/python3.12/site-packages/discord/http.py", line 2999, in get_gateway
    data = await self.request(Route("GET", "/gateway"))
           ^^^^^^^^^^^^^^^^^^^^^^^^^^^^^^^^^^^^^^^^^^^^
  File "/Users/campusheilbronn/PycharmProjects/TUMDiscordBot/.venv/lib/python3.12/site-packages/discord/http.py", line 285, in request
    async with self.__session.request(
               ^^^^^^^^^^^^^^^^^^^^^^^
  File "/Users/campusheilbronn/PycharmProjects/TUMDiscordBot/.venv/lib/python3.12/site-packages/aiohttp/client.py", line 1423, in __aenter__
    self._resp: _RetType = await self._coro
                           ^^^^^^^^^^^^^^^^
  File "/Users/campusheilbronn/PycharmProjects/TUMDiscordBot/.venv/lib/python3.12/site-packages/aiohttp/client.py", line 701, in _request
    conn = await self._connector.connect(
           ^^^^^^^^^^^^^^^^^^^^^^^^^^^^^^
  File "/Users/campusheilbronn/PycharmProjects/TUMDiscordBot/.venv/lib/python3.12/site-packages/aiohttp/connector.py", line 544, in connect
    proto = await self._create_connection(req, traces, timeout)
            ^^^^^^^^^^^^^^^^^^^^^^^^^^^^^^^^^^^^^^^^^^^^^^^^^^^
  File "/Users/campusheilbronn/PycharmProjects/TUMDiscordBot/.venv/lib/python3.12/site-packages/aiohttp/connector.py", line 1050, in _create_connection
    _, proto = await self._create_direct_connection(req, traces, timeout)
               ^^^^^^^^^^^^^^^^^^^^^^^^^^^^^^^^^^^^^^^^^^^^^^^^^^^^^^^^^^
  File "/Users/campusheilbronn/PycharmProjects/TUMDiscordBot/.venv/lib/python3.12/site-packages/aiohttp/connector.py", line 1351, in _create_direct_connection
    raise ClientConnectorDNSError(req.connection_key, exc) from exc
aiohttp.client_exceptions.ClientConnectorDNSError: Cannot connect to host discord.com:443 ssl:default [nodename nor servname provided, or not known]
